Workbook

Sheet summary 
A1: # | B1: Category | C1: Count
A2: 1 | B2: Bug | C2: =COUNTIF('Observations '!D2:D1000,"Bug") -> 16
A3: 2 | B3: Enhancement | C3: =COUNTIF('Observations '!D2:D1000,"Enhancements") -> 25
A4: 3 | B4: Enhancement (Productization) | C4: =COUNTIF('Observations '!D2:D1000,"Enahancement (Productization)") -> 16
A5: 4 | B5: Clarification | C5: =COUNTIF('Observations '!D2:D1000,"Clarification") -> 19
A6: 5 | B6: No Change Required | C6: =COUNTIF('Observations '!D2:D1000,"No Change Required") -> 4
A7: 6 | B7: Other / Misc (Purging, Archiving, Landscape, etc.) | C7: =C8-C2-C3-C4-C5-C6 -> 8
A8: GRAND TOTAL | C8: =COUNTA('Observations '!D2:D1000)-COUNTIF('Observations '!D2:D1000,"Category Bug/Productization/New/Edit/Bug") -> 88
A10: # | B10: Priority | C10: Bug | D10: Enhancement | E10: Enh. (Productization) | F10: Clarification | G10: No Change Req. | H10: Other/Misc | I10: TOTAL
A11: 1 | B11: High | C11: 11 | D11: 10 | E11: 4 | F11: 0 | G11: 0 | H11: 2 | I11: 27
A12: 2 | B12: Medium | C12: 1 | D12: 10 | E12: 1 | F12: 0 | G12: 0 | H12: 1 | I12: 13
A13: 3 | B13: Low | C13: 2 | D13: 5 | E13: 10 | F13: 0 | G13: 0 | H13: 0 | I13: 17
A14: 4 | B14: NA / Blank | C14: 2 | D14: 0 | E14: 1 | F14: 19 | G14: 4 | H14: 5 | I14: 31
B15: TOTAL | C15: 16 | D15: 25 | E15: 16 | F15: 19 | G15: 4 | H15: 8 | I15: 88
A17: # | B17: Status | C17: Bug | D17: Enhancement | E17: Enh. (Productization) | F17: Clarification | G17: No Change Req. | H17: Other/Misc | I17: TOTAL
A18: 1 | B18: To Be Taken Up | C18: =COUNTIFS('Observations '!D2:D1000,"Bug",'Observations '!M2:M1000,"To be taken up")+COUNTIFS('Observations '!D2:D1000,"Bug",'Observations '!M2:M1000,"To be discussed and taken up")+COUNTIFS('Observations '!D2:D1000,"Bug",'Observations '!M2:M1000,"To be taken up after the collection of probable vendor names")+COUNTIFS('Observations '!D2:D1000,"Bug",'Observations '!M2:M1000,"To be done as a another asset type") -> 15 | D18: =COUNTIFS('Observations '!D2:D1000,"Enhancements",'Observations '!M2:M1000,"To be taken up")+COUNTIFS('Observations '!D2:D1000,"Enhancements",'Observations '!M2:M1000,"To be discussed and taken up")+COUNTIFS('Observations '!D2:D1000,"Enhancements",'Observations '!M2:M1000,"To be taken up after the collection of probable vendor names")+COUNTIFS('Observations '!D2:D1000,"Enhancements",'Observations '!M2:M1000,"To be done as a another asset type") -> 13 | E18: =COUNTIFS('Observations '!D2:D1000,"Enahancement (Productization)",'Observations '!M2:M1000,"To be taken up")+COUNTIFS('Observations '!D2:D1000,"Enahancement (Productization)",'Observations '!M2:M1000,"To be discussed and taken up")+COUNTIFS('Observations '!D2:D1000,"Enahancement (Productization)",'Observations '!M2:M1000,"To be taken up after the collection of probable vendor names")+COUNTIFS('Observations '!D2:D1000,"Enahancement (Productization)",'Observations '!M2:M1000,"To be done as a another asset type") -> 5 | F18: =COUNTIFS('Observations '!D2:D1000,"Clarification",'Observations '!M2:M1000,"To be taken up")+COUNTIFS('Observations '!D2:D1000,"Clarification",'Observations '!M2:M1000,"To be discussed and taken up")+COUNTIFS('Observations '!D2:D1000,"Clarification",'Observations '!M2:M1000,"To be taken up after the collection of probable vendor names")+COUNTIFS('Observations '!D2:D1000,"Clarification",'Observations '!M2:M1000,"To be done as a another asset type") -> 0 | G18: =COUNTIFS('Observations '!D2:D1000,"No Change Required",'Observations '!M2:M1000,"To be taken up")+COUNTIFS('Observations '!D2:D1000,"No Change Required",'Observations '!M2:M1000,"To be discussed and taken up")+COUNTIFS('Observations '!D2:D1000,"No Change Required",'Observations '!M2:M1000,"To be taken up after the collection of probable vendor names")+COUNTIFS('Observations '!D2:D1000,"No Change Required",'Observations '!M2:M1000,"To be done as a another asset type") -> 0 | H18: =COUNTIF('Observations '!M2:M1000,"To be taken up")+COUNTIF('Observations '!M2:M1000,"To be discussed and taken up")+COUNTIF('Observations '!M2:M1000,"To be taken up after the collection of probable vendor names")+COUNTIF('Observations '!M2:M1000,"To be done as a another asset type")-COUNTIFS('Observations '!D2:D1000,"Bug",'Observations '!M2:M1000,"To be taken up")-COUNTIFS('Observations '!D2:D1000,"Bug",'Observations '!M2:M1000,"To be discussed and taken up")-COUNTIFS('Observations '!D2:D1000,"Bug",'Observations '!M2:M1000,"To be taken up after the collection of probable vendor names")-COUNTIFS('Observations '!D2:D1000,"Bug",'Observations '!M2:M1000,"To be done as a another asset type")-COUNTIFS('Observations '!D2:D1000,"Enhancements",'Observations '!M2:M1000,"To be taken up")-COUNTIFS('Observations '!D2:D1000,"Enhancements",'Observations '!M2:M1000,"To be discussed and taken up")-COUNTIFS('Observations '!D2:D1000,"Enhancements",'Observations '!M2:M1000,"To be taken up after the collection of probable vendor names")-COUNTIFS('Observations '!D2:D1000,"Enhancements",'Observations '!M2:M1000,"To be done as a another asset type")-COUNTIFS('Observations '!D2:D1000,"Enahancement (Productization)",'Observations '!M2:M1000,"To be taken up")-COUNTIFS('Observations '!D2:D1000,"Enahancement (Productization)",'Observations '!M2:M1000,"To be discussed and taken up")-COUNTIFS('Observations '!D2:D1000,"Enahancement (Productization)",'Observations '!M2:M1000,"To be taken up after the collection of probable vendor names")-COUNTIFS('Observations '!D2:D1000,"Enahancement (Productization)",'Observations '!M2:M1000,"To be done as a another asset type")-COUNTIFS('Observations '!D2:D1000,"Clarification",'Observations '!M2:M1000,"To be taken up")-COUNTIFS('Observations '!D2:D1000,"Clarification",'Observations '!M2:M1000,"To be discussed and taken up")-COUNTIFS('Observations '!D2:D1000,"Clarification",'Observations '!M2:M1000,"To be taken up after the collection of probable vendor names")-COUNTIFS('Observations '!D2:D1000,"Clarification",'Observations '!M2:M1000,"To be done as a another asset type")-COUNTIFS('Observations '!D2:D1000,"No Change Required",'Observations '!M2:M1000,"To be taken up")-COUNTIFS('Observations '!D2:D1000,"No Change Required",'Observations '!M2:M1000,"To be discussed and taken up")-COUNTIFS('Observations '!D2:D1000,"No Change Required",'Observations '!M2:M1000,"To be taken up after the collection of probable vendor names")-COUNTIFS('Observations '!D2:D1000,"No Change Required",'Observations '!M2:M1000,"To be done as a another asset type") -> 1 | I18: =C18+D18+E18+F18+G18+H18 -> 34
A19: 2 | B19: WIP | C19: =COUNTIFS('Observations '!D2:D1000,"Bug",'Observations '!M2:M1000,"WIP") -> 0 | D19: =COUNTIFS('Observations '!D2:D1000,"Enhancements",'Observations '!M2:M1000,"WIP") -> 4 | E19: =COUNTIFS('Observations '!D2:D1000,"Enahancement (Productization)",'Observations '!M2:M1000,"WIP") -> 4 | F19: =COUNTIFS('Observations '!D2:D1000,"Clarification",'Observations '!M2:M1000,"WIP") -> 0 | G19: =COUNTIFS('Observations '!D2:D1000,"No Change Required",'Observations '!M2:M1000,"WIP") -> 1 | H19: =COUNTIF('Observations '!M2:M1000,"WIP")-COUNTIFS('Observations '!D2:D1000,"Bug",'Observations '!M2:M1000,"WIP")-COUNTIFS('Observations '!D2:D1000,"Enhancements",'Observations '!M2:M1000,"WIP")-COUNTIFS('Observations '!D2:D1000,"Enahancement (Productization)",'Observations '!M2:M1000,"WIP")-COUNTIFS('Observations '!D2:D1000,"Clarification",'Observations '!M2:M1000,"WIP")-COUNTIFS('Observations '!D2:D1000,"No Change Required",'Observations '!M2:M1000,"WIP") -> 0 | I19: =C19+D19+E19+F19+G19+H19 -> 9
A20: 3 | B20: Closed | C20: =COUNTIFS('Observations '!D2:D1000,"Bug",'Observations '!M2:M1000,"Closed") -> 0 | D20: =COUNTIFS('Observations '!D2:D1000,"Enhancements",'Observations '!M2:M1000,"Closed") -> 1 | E20: =COUNTIFS('Observations '!D2:D1000,"Enahancement (Productization)",'Observations '!M2:M1000,"Closed") -> 0 | F20: =COUNTIFS('Observations '!D2:D1000,"Clarification",'Observations '!M2:M1000,"Closed") -> 16 | G20: =COUNTIFS('Observations '!D2:D1000,"No Change Required",'Observations '!M2:M1000,"Closed") -> 3 | H20: =COUNTIF('Observations '!M2:M1000,"Closed")-COUNTIFS('Observations '!D2:D1000,"Bug",'Observations '!M2:M1000,"Closed")-COUNTIFS('Observations '!D2:D1000,"Enhancements",'Observations '!M2:M1000,"Closed")-COUNTIFS('Observations '!D2:D1000,"Enahancement (Productization)",'Observations '!M2:M1000,"Closed")-COUNTIFS('Observations '!D2:D1000,"Clarification",'Observations '!M2:M1000,"Closed")-COUNTIFS('Observations '!D2:D1000,"No Change Required",'Observations '!M2:M1000,"Closed") -> 0 | I20: =C20+D20+E20+F20+G20+H20 -> 20
A21: 4 | B21: Need to Study/Analyze | C21: =COUNTIFS('Observations '!D2:D1000,"Bug",'Observations '!M2:M1000,"Need to study")+COUNTIFS('Observations '!D2:D1000,"Bug",'Observations '!M2:M1000,"To be studied")+COUNTIFS('Observations '!D2:D1000,"Bug",'Observations '!M2:M1000,"To be studied further")+COUNTIFS('Observations '!D2:D1000,"Bug",'Observations '!M2:M1000,"To be analyzed")+COUNTIFS('Observations '!D2:D1000,"Bug",'Observations '!M2:M1000,"To be analyzed the impact and feasibility")+COUNTIFS('Observations '!D2:D1000,"Bug",'Observations '!M2:M1000,"To be studied and add ational things prior to implementation") -> 1 | D21: =COUNTIFS('Observations '!D2:D1000,"Enhancements",'Observations '!M2:M1000,"Need to study")+COUNTIFS('Observations '!D2:D1000,"Enhancements",'Observations '!M2:M1000,"To be studied")+COUNTIFS('Observations '!D2:D1000,"Enhancements",'Observations '!M2:M1000,"To be studied further")+COUNTIFS('Observations '!D2:D1000,"Enhancements",'Observations '!M2:M1000,"To be analyzed")+COUNTIFS('Observations '!D2:D1000,"Enhancements",'Observations '!M2:M1000,"To be analyzed the impact and feasibility")+COUNTIFS('Observations '!D2:D1000,"Enhancements",'Observations '!M2:M1000,"To be studied and add ational things prior to implementation") -> 7 | E21: =COUNTIFS('Observations '!D2:D1000,"Enahancement (Productization)",'Observations '!M2:M1000,"Need to study")+COUNTIFS('Observations '!D2:D1000,"Enahancement (Productization)",'Observations '!M2:M1000,"To be studied")+COUNTIFS('Observations '!D2:D1000,"Enahancement (Productization)",'Observations '!M2:M1000,"To be studied further")+COUNTIFS('Observations '!D2:D1000,"Enahancement (Productization)",'Observations '!M2:M1000,"To be analyzed")+COUNTIFS('Observations '!D2:D1000,"Enahancement (Productization)",'Observations '!M2:M1000,"To be analyzed the impact and feasibility")+COUNTIFS('Observations '!D2:D1000,"Enahancement (Productization)",'Observations '!M2:M1000,"To be studied and add ational things prior to implementation") -> 6 | F21: =COUNTIFS('Observations '!D2:D1000,"Clarification",'Observations '!M2:M1000,"Need to study")+COUNTIFS('Observations '!D2:D1000,"Clarification",'Observations '!M2:M1000,"To be studied")+COUNTIFS('Observations '!D2:D1000,"Clarification",'Observations '!M2:M1000,"To be studied further")+COUNTIFS('Observations '!D2:D1000,"Clarification",'Observations '!M2:M1000,"To be analyzed")+COUNTIFS('Observations '!D2:D1000,"Clarification",'Observations '!M2:M1000,"To be analyzed the impact and feasibility")+COUNTIFS('Observations '!D2:D1000,"Clarification",'Observations '!M2:M1000,"To be studied and add ational things prior to implementation") -> 2 | G21: =COUNTIFS('Observations '!D2:D1000,"No Change Required",'Observations '!M2:M1000,"Need to study")+COUNTIFS('Observations '!D2:D1000,"No Change Required",'Observations '!M2:M1000,"To be studied")+COUNTIFS('Observations '!D2:D1000,"No Change Required",'Observations '!M2:M1000,"To be studied further")+COUNTIFS('Observations '!D2:D1000,"No Change Required",'Observations '!M2:M1000,"To be analyzed")+COUNTIFS('Observations '!D2:D1000,"No Change Required",'Observations '!M2:M1000,"To be analyzed the impact and feasibility")+COUNTIFS('Observations '!D2:D1000,"No Change Required",'Observations '!M2:M1000,"To be studied and add ational things prior to implementation") -> 0 | H21: =COUNTIF('Observations '!M2:M1000,"Need to study")+COUNTIF('Observations '!M2:M1000,"To be studied")+COUNTIF('Observations '!M2:M1000,"To be studied further")+COUNTIF('Observations '!M2:M1000,"To be analyzed")+COUNTIF('Observations '!M2:M1000,"To be analyzed the impact and feasibility")+COUNTIF('Observations '!M2:M1000,"To be studied and add ational things prior to implementation")-COUNTIFS('Observations '!D2:D1000,"Bug",'Observations '!M2:M1000,"Need to study")-COUNTIFS('Observations '!D2:D1000,"Bug",'Observations '!M2:M1000,"To be studied")-COUNTIFS('Observations '!D2:D1000,"Bug",'Observations '!M2:M1000,"To be studied further")-COUNTIFS('Observations '!D2:D1000,"Bug",'Observations '!M2:M1000,"To be analyzed")-COUNTIFS('Observations '!D2:D1000,"Bug",'Observations '!M2:M1000,"To be analyzed the impact and feasibility")-COUNTIFS('Observations '!D2:D1000,"Bug",'Observations '!M2:M1000,"To be studied and add ational things prior to implementation")-COUNTIFS('Observations '!D2:D1000,"Enhancements",'Observations '!M2:M1000,"Need to study")-COUNTIFS('Observations '!D2:D1000,"Enhancements",'Observations '!M2:M1000,"To be studied")-COUNTIFS('Observations '!D2:D1000,"Enhancements",'Observations '!M2:M1000,"To be studied further")-COUNTIFS('Observations '!D2:D1000,"Enhancements",'Observations '!M2:M1000,"To be analyzed")-COUNTIFS('Observations '!D2:D1000,"Enhancements",'Observations '!M2:M1000,"To be analyzed the impact and feasibility")-COUNTIFS('Observations '!D2:D1000,"Enhancements",'Observations '!M2:M1000,"To be studied and add ational things prior to implementation")-COUNTIFS('Observations '!D2:D1000,"Enahancement (Productization)",'Observations '!M2:M1000,"Need to study")-COUNTIFS('Observations '!D2:D1000,"Enahancement (Productization)",'Observations '!M2:M1000,"To be studied")-COUNTIFS('Observations '!D2:D1000,"Enahancement (Productization)",'Observations '!M2:M1000,"To be studied further")-COUNTIFS('Observations '!D2:D1000,"Enahancement (Productization)",'Observations '!M2:M1000,"To be analyzed")-COUNTIFS('Observations '!D2:D1000,"Enahancement (Productization)",'Observations '!M2:M1000,"To be analyzed the impact and feasibility")-COUNTIFS('Observations '!D2:D1000,"Enahancement (Productization)",'Observations '!M2:M1000,"To be studied and add ational things prior to implementation")-COUNTIFS('Observations '!D2:D1000,"Clarification",'Observations '!M2:M1000,"Need to study")-COUNTIFS('Observations '!D2:D1000,"Clarification",'Observations '!M2:M1000,"To be studied")-COUNTIFS('Observations '!D2:D1000,"Clarification",'Observations '!M2:M1000,"To be studied further")-COUNTIFS('Observations '!D2:D1000,"Clarification",'Observations '!M2:M1000,"To be analyzed")-COUNTIFS('Observations '!D2:D1000,"Clarification",'Observations '!M2:M1000,"To be analyzed the impact and feasibility")-COUNTIFS('Observations '!D2:D1000,"Clarification",'Observations '!M2:M1000,"To be studied and add ational things prior to implementation")-COUNTIFS('Observations '!D2:D1000,"No Change Required",'Observations '!M2:M1000,"Need to study")-COUNTIFS('Observations '!D2:D1000,"No Change Required",'Observations '!M2:M1000,"To be studied")-COUNTIFS('Observations '!D2:D1000,"No Change Required",'Observations '!M2:M1000,"To be studied further")-COUNTIFS('Observations '!D2:D1000,"No Change Required",'Observations '!M2:M1000,"To be analyzed")-COUNTIFS('Observations '!D2:D1000,"No Change Required",'Observations '!M2:M1000,"To be analyzed the impact and feasibility")-COUNTIFS('Observations '!D2:D1000,"No Change Required",'Observations '!M2:M1000,"To be studied and add ational things prior to implementation") -> 0 | I21: =C21+D21+E21+F21+G21+H21 -> 16
A22: 5 | B22: To Be Done | C22: =COUNTIFS('Observations '!D2:D1000,"Bug",'Observations '!M2:M1000,"To be done as a another asset type") -> 0 | D22: =COUNTIFS('Observations '!D2:D1000,"Enhancements",'Observations '!M2:M1000,"To be done as a another asset type") -> 0 | E22: =COUNTIFS('Observations '!D2:D1000,"Enahancement (Productization)",'Observations '!M2:M1000,"To be done as a another asset type") -> 4 | F22: =COUNTIFS('Observations '!D2:D1000,"Clarification",'Observations '!M2:M1000,"To be done as a another asset type") -> 0 | G22: =COUNTIFS('Observations '!D2:D1000,"No Change Required",'Observations '!M2:M1000,"To be done as a another asset type") -> 0 | H22: =COUNTIF('Observations '!M2:M1000,"To be done as a another asset type")-COUNTIFS('Observations '!D2:D1000,"Bug",'Observations '!M2:M1000,"To be done as a another asset type")-COUNTIFS('Observations '!D2:D1000,"Enhancements",'Observations '!M2:M1000,"To be done as a another asset type")-COUNTIFS('Observations '!D2:D1000,"Enahancement (Productization)",'Observations '!M2:M1000,"To be done as a another asset type")-COUNTIFS('Observations '!D2:D1000,"Clarification",'Observations '!M2:M1000,"To be done as a another asset type")-COUNTIFS('Observations '!D2:D1000,"No Change Required",'Observations '!M2:M1000,"To be done as a another asset type") -> 0 | I22: =C22+D22+E22+F22+G22+H22 -> 4
A23: 6 | B23: To Be Tested | C23: =COUNTIFS('Observations '!D2:D1000,"Bug",'Observations '!M2:M1000,"TO be Tested") -> 0 | D23: =COUNTIFS('Observations '!D2:D1000,"Enhancements",'Observations '!M2:M1000,"TO be Tested") -> 0 | E23: =COUNTIFS('Observations '!D2:D1000,"Enahancement (Productization)",'Observations '!M2:M1000,"TO be Tested") -> 0 | F23: =COUNTIFS('Observations '!D2:D1000,"Clarification",'Observations '!M2:M1000,"TO be Tested") -> 0 | G23: =COUNTIFS('Observations '!D2:D1000,"No Change Required",'Observations '!M2:M1000,"TO be Tested") -> 0 | H23: =COUNTIF('Observations '!M2:M1000,"TO be Tested")-COUNTIFS('Observations '!D2:D1000,"Bug",'Observations '!M2:M1000,"TO be Tested")-COUNTIFS('Observations '!D2:D1000,"Enhancements",'Observations '!M2:M1000,"TO be Tested")-COUNTIFS('Observations '!D2:D1000,"Enahancement (Productization)",'Observations '!M2:M1000,"TO be Tested")-COUNTIFS('Observations '!D2:D1000,"Clarification",'Observations '!M2:M1000,"TO be Tested")-COUNTIFS('Observations '!D2:D1000,"No Change Required",'Observations '!M2:M1000,"TO be Tested") -> 2 | I23: =C23+D23+E23+F23+G23+H23 -> 2
A24: 7 | B24: Repeated | C24: =COUNTIFS('Observations '!D2:D1000,"Bug",'Observations '!M2:M1000,"Repeated") -> 0 | D24: =COUNTIFS('Observations '!D2:D1000,"Enhancements",'Observations '!M2:M1000,"Repeated") -> 0 | E24: =COUNTIFS('Observations '!D2:D1000,"Enahancement (Productization)",'Observations '!M2:M1000,"Repeated") -> 1 | F24: =COUNTIFS('Observations '!D2:D1000,"Clarification",'Observations '!M2:M1000,"Repeated") -> 0 | G24: =COUNTIFS('Observations '!D2:D1000,"No Change Required",'Observations '!M2:M1000,"Repeated") -> 0 | H24: =COUNTIF('Observations '!M2:M1000,"Repeated")-COUNTIFS('Observations '!D2:D1000,"Bug",'Observations '!M2:M1000,"Repeated")-COUNTIFS('Observations '!D2:D1000,"Enhancements",'Observations '!M2:M1000,"Repeated")-COUNTIFS('Observations '!D2:D1000,"Enahancement (Productization)",'Observations '!M2:M1000,"Repeated")-COUNTIFS('Observations '!D2:D1000,"Clarification",'Observations '!M2:M1000,"Repeated")-COUNTIFS('Observations '!D2:D1000,"No Change Required",'Observations '!M2:M1000,"Repeated") -> 0 | I24: =C24+D24+E24+F24+G24+H24 -> 1
A25: 8 | B25: Not Yet Finalized | C25: =COUNTIFS('Observations '!D2:D1000,"Bug",'Observations '!M2:M1000,"Requirements not yet Finalised") -> 0 | D25: =COUNTIFS('Observations '!D2:D1000,"Enhancements",'Observations '!M2:M1000,"Requirements not yet Finalised") -> 0 | E25: =COUNTIFS('Observations '!D2:D1000,"Enahancement (Productization)",'Observations '!M2:M1000,"Requirements not yet Finalised") -> 0 | F25: =COUNTIFS('Observations '!D2:D1000,"Clarification",'Observations '!M2:M1000,"Requirements not yet Finalised") -> 0 | G25: =COUNTIFS('Observations '!D2:D1000,"No Change Required",'Observations '!M2:M1000,"Requirements not yet Finalised") -> 0 | H25: =COUNTIF('Observations '!M2:M1000,"Requirements not yet Finalised")-COUNTIFS('Observations '!D2:D1000,"Bug",'Observations '!M2:M1000,"Requirements not yet Finalised")-COUNTIFS('Observations '!D2:D1000,"Enhancements",'Observations '!M2:M1000,"Requirements not yet Finalised")-COUNTIFS('Observations '!D2:D1000,"Enahancement (Productization)",'Observations '!M2:M1000,"Requirements not yet Finalised")-COUNTIFS('Observations '!D2:D1000,"Clarification",'Observations '!M2:M1000,"Requirements not yet Finalised")-COUNTIFS('Observations '!D2:D1000,"No Change Required",'Observations '!M2:M1000,"Requirements not yet Finalised") -> 2 | I25: =C25+D25+E25+F25+G25+H25 -> 2
B26: TOTAL | C26: =SUM(C18:C25) -> 16 | D26: =SUM(D18:D25) -> 25 | E26: =SUM(E18:E25) -> 20 | F26: =SUM(F18:F25) -> 18 | G26: =SUM(G18:G25) -> 4 | H26: =SUM(H18:H25) -> 5 | I26: =SUM(I18:I25) -> 88

Sheet summ
B2: Criteria → | E2: Bug | F2: Enhancements | G2: Clarification | I2: High | J2: Low | K2: Medium
F3: Enahancement (Productization) | I3: HIGH | J3: LOW
E4: =SUM(E6:E51) -> 17 | F4: =SUM(F6:F51) -> 55 | G4: =SUM(G6:G51) -> 31 | H4: =SUM(H6:H51) -> 18 | I4: =SUM(I6:I51) -> 60 | J4: =SUM(J6:J51) -> 46 | K4: =SUM(K6:K51) -> 17
B5: S.No | C5: Menu Item | D5: Sub Menu Item | E5: BUG | F5: ENHANCEMENT | G5: CLARIFICATION | H5: OTHERS | I5: HIGH | J5: LOW | K5: MEDIUM | L5: TOTAL
A6: DB | B6: 1 | C6: Dashboard | D6: SR | E6: =COUNTIFS('Observations '!$G:$G,"*"&C6&"*",'Observations '!$H:$H,IF(D6="","",D6),'Observations '!$D:$D,$E$2) -> 1 | F6: =COUNTIFS('Observations '!$G:$G,"*"&C6&"*",'Observations '!$H:$H,IF(D6="","",D6),'Observations '!$D:$D,$F$2)+COUNTIFS('Observations '!$G:$G,"*"&C6&"*",'Observations '!$H:$H,IF(D6="","",D6),'Observations '!$D:$D,$F$3) -> 0 | G6: =COUNTIFS('Observations '!$G:$G,"*"&C6&"*",'Observations '!$H:$H,IF(D6="","",D6),'Observations '!$D:$D,$G$2) -> 0 | H6: =L6-E6-F6-G6 -> 1 | I6: =COUNTIFS('Observations '!$G:$G,"*"&C6&"*",'Observations '!$H:$H,IF(D6="","",D6),'Observations '!$E:$E,$I$2)+COUNTIFS('Observations '!$G:$G,"*"&C6&"*",'Observations '!$H:$H,IF(D6="","",D6),'Observations '!$E:$E,$I$3) -> 0 | J6: =COUNTIFS('Observations '!$G:$G,"*"&C6&"*",'Observations '!$H:$H,IF(D6="","",D6),'Observations '!$E:$E,$J$2)+COUNTIFS('Observations '!$G:$G,"*"&C6&"*",'Observations '!$H:$H,IF(D6="","",D6),'Observations '!$E:$E,$J$3) -> 2 | K6: =COUNTIFS('Observations '!$G:$G,"*"&C6&"*",'Observations '!$H:$H,IF(D6="","",D6),'Observations '!$E:$E,$K$2) -> 0 | L6: =SUM(I6:K6) -> 2
A7: DB | B7: 2 | C7: Dashboard | D7: PTW | E7: =COUNTIFS('Observations '!$G:$G,"*"&C7&"*",'Observations '!$H:$H,IF(D7="","",D7),'Observations '!$D:$D,$E$2) -> 1 | F7: =COUNTIFS('Observations '!$G:$G,"*"&C7&"*",'Observations '!$H:$H,IF(D7="","",D7),'Observations '!$D:$D,$F$2)+COUNTIFS('Observations '!$G:$G,"*"&C7&"*",'Observations '!$H:$H,IF(D7="","",D7),'Observations '!$D:$D,$F$3) -> 0 | G7: =COUNTIFS('Observations '!$G:$G,"*"&C7&"*",'Observations '!$H:$H,IF(D7="","",D7),'Observations '!$D:$D,$G$2) -> 0 | H7: =L7-E7-F7-G7 -> 1 | I7: =COUNTIFS('Observations '!$G:$G,"*"&C7&"*",'Observations '!$H:$H,IF(D7="","",D7),'Observations '!$E:$E,$I$2)+COUNTIFS('Observations '!$G:$G,"*"&C7&"*",'Observations '!$H:$H,IF(D7="","",D7),'Observations '!$E:$E,$I$3) -> 2 | J7: =COUNTIFS('Observations '!$G:$G,"*"&C7&"*",'Observations '!$H:$H,IF(D7="","",D7),'Observations '!$E:$E,$J$2)+COUNTIFS('Observations '!$G:$G,"*"&C7&"*",'Observations '!$H:$H,IF(D7="","",D7),'Observations '!$E:$E,$J$3) -> 0 | K7: =COUNTIFS('Observations '!$G:$G,"*"&C7&"*",'Observations '!$H:$H,IF(D7="","",D7),'Observations '!$E:$E,$K$2) -> 0 | L7: =SUM(I7:K7) -> 2
A8: DB | B8: 3 | C8: Dashboard | D8: UES | E8: =COUNTIFS('Observations '!$G:$G,"*"&C8&"*",'Observations '!$H:$H,IF(D8="","",D8),'Observations '!$D:$D,$E$2) -> 1 | F8: =COUNTIFS('Observations '!$G:$G,"*"&C8&"*",'Observations '!$H:$H,IF(D8="","",D8),'Observations '!$D:$D,$F$2)+COUNTIFS('Observations '!$G:$G,"*"&C8&"*",'Observations '!$H:$H,IF(D8="","",D8),'Observations '!$D:$D,$F$3) -> 1 | G8: =COUNTIFS('Observations '!$G:$G,"*"&C8&"*",'Observations '!$H:$H,IF(D8="","",D8),'Observations '!$D:$D,$G$2) -> 1 | H8: =L8-E8-F8-G8 -> 1 | I8: =COUNTIFS('Observations '!$G:$G,"*"&C8&"*",'Observations '!$H:$H,IF(D8="","",D8),'Observations '!$E:$E,$I$2)+COUNTIFS('Observations '!$G:$G,"*"&C8&"*",'Observations '!$H:$H,IF(D8="","",D8),'Observations '!$E:$E,$I$3) -> 2 | J8: =COUNTIFS('Observations '!$G:$G,"*"&C8&"*",'Observations '!$H:$H,IF(D8="","",D8),'Observations '!$E:$E,$J$2)+COUNTIFS('Observations '!$G:$G,"*"&C8&"*",'Observations '!$H:$H,IF(D8="","",D8),'Observations '!$E:$E,$J$3) -> 2 | K8: =COUNTIFS('Observations '!$G:$G,"*"&C8&"*",'Observations '!$H:$H,IF(D8="","",D8),'Observations '!$E:$E,$K$2) -> 0 | L8: =SUM(I8:K8) -> 4
A9: Meter | B9: 4 | C9: Maintenance Shop | D9: Meter Rollovers | E9: =COUNTIFS('Observations '!$G:$G,"*"&C9&"*",'Observations '!$H:$H,IF(D9="","",D9),'Observations '!$D:$D,$E$2) -> 1 | F9: =COUNTIFS('Observations '!$G:$G,"*"&C9&"*",'Observations '!$H:$H,IF(D9="","",D9),'Observations '!$D:$D,$F$2)+COUNTIFS('Observations '!$G:$G,"*"&C9&"*",'Observations '!$H:$H,IF(D9="","",D9),'Observations '!$D:$D,$F$3) -> 0 | G9: =COUNTIFS('Observations '!$G:$G,"*"&C9&"*",'Observations '!$H:$H,IF(D9="","",D9),'Observations '!$D:$D,$G$2) -> 0 | H9: =L9-E9-F9-G9 -> 1 | I9: =COUNTIFS('Observations '!$G:$G,"*"&C9&"*",'Observations '!$H:$H,IF(D9="","",D9),'Observations '!$E:$E,$I$2)+COUNTIFS('Observations '!$G:$G,"*"&C9&"*",'Observations '!$H:$H,IF(D9="","",D9),'Observations '!$E:$E,$I$3) -> 2 | J9: =COUNTIFS('Observations '!$G:$G,"*"&C9&"*",'Observations '!$H:$H,IF(D9="","",D9),'Observations '!$E:$E,$J$2)+COUNTIFS('Observations '!$G:$G,"*"&C9&"*",'Observations '!$H:$H,IF(D9="","",D9),'Observations '!$E:$E,$J$3) -> 0 | K9: =COUNTIFS('Observations '!$G:$G,"*"&C9&"*",'Observations '!$H:$H,IF(D9="","",D9),'Observations '!$E:$E,$K$2) -> 0 | L9: =SUM(I9:K9) -> 2
A10: Meter | B10: 5 | C10: Maintenance Shop | D10: Meter Replacements | E10: =COUNTIFS('Observations '!$G:$G,"*"&C10&"*",'Observations '!$H:$H,IF(D10="","",D10),'Observations '!$D:$D,$E$2) -> 1 | F10: =COUNTIFS('Observations '!$G:$G,"*"&C10&"*",'Observations '!$H:$H,IF(D10="","",D10),'Observations '!$D:$D,$F$2)+COUNTIFS('Observations '!$G:$G,"*"&C10&"*",'Observations '!$H:$H,IF(D10="","",D10),'Observations '!$D:$D,$F$3) -> 0 | G10: =COUNTIFS('Observations '!$G:$G,"*"&C10&"*",'Observations '!$H:$H,IF(D10="","",D10),'Observations '!$D:$D,$G$2) -> 0 | H10: =L10-E10-F10-G10 -> 1 | I10: =COUNTIFS('Observations '!$G:$G,"*"&C10&"*",'Observations '!$H:$H,IF(D10="","",D10),'Observations '!$E:$E,$I$2)+COUNTIFS('Observations '!$G:$G,"*"&C10&"*",'Observations '!$H:$H,IF(D10="","",D10),'Observations '!$E:$E,$I$3) -> 2 | J10: =COUNTIFS('Observations '!$G:$G,"*"&C10&"*",'Observations '!$H:$H,IF(D10="","",D10),'Observations '!$E:$E,$J$2)+COUNTIFS('Observations '!$G:$G,"*"&C10&"*",'Observations '!$H:$H,IF(D10="","",D10),'Observations '!$E:$E,$J$3) -> 0 | K10: =COUNTIFS('Observations '!$G:$G,"*"&C10&"*",'Observations '!$H:$H,IF(D10="","",D10),'Observations '!$E:$E,$K$2) -> 0 | L10: =SUM(I10:K10) -> 2
A11: Meter | B11: 6 | C11: Maintenance Shop | D11: Meter replacement | E11: =COUNTIFS('Observations '!$G:$G,"*"&C11&"*",'Observations '!$H:$H,IF(D11="","",D11),'Observations '!$D:$D,$E$2) -> 1 | F11: =COUNTIFS('Observations '!$G:$G,"*"&C11&"*",'Observations '!$H:$H,IF(D11="","",D11),'Observations '!$D:$D,$F$2)+COUNTIFS('Observations '!$G:$G,"*"&C11&"*",'Observations '!$H:$H,IF(D11="","",D11),'Observations '!$D:$D,$F$3) -> 0 | G11: =COUNTIFS('Observations '!$G:$G,"*"&C11&"*",'Observations '!$H:$H,IF(D11="","",D11),'Observations '!$D:$D,$G$2) -> 0 | H11: =L11-E11-F11-G11 -> 1 | I11: =COUNTIFS('Observations '!$G:$G,"*"&C11&"*",'Observations '!$H:$H,IF(D11="","",D11),'Observations '!$E:$E,$I$2)+COUNTIFS('Observations '!$G:$G,"*"&C11&"*",'Observations '!$H:$H,IF(D11="","",D11),'Observations '!$E:$E,$I$3) -> 2 | J11: =COUNTIFS('Observations '!$G:$G,"*"&C11&"*",'Observations '!$H:$H,IF(D11="","",D11),'Observations '!$E:$E,$J$2)+COUNTIFS('Observations '!$G:$G,"*"&C11&"*",'Observations '!$H:$H,IF(D11="","",D11),'Observations '!$E:$E,$J$3) -> 0 | K11: =COUNTIFS('Observations '!$G:$G,"*"&C11&"*",'Observations '!$H:$H,IF(D11="","",D11),'Observations '!$E:$E,$K$2) -> 0 | L11: =SUM(I11:K11) -> 2
A12: Meter | B12: 7 | C12: Maintenance Shop | D12: Meter rollover | E12: =COUNTIFS('Observations '!$G:$G,"*"&C12&"*",'Observations '!$H:$H,IF(D12="","",D12),'Observations '!$D:$D,$E$2) -> 1 | F12: =COUNTIFS('Observations '!$G:$G,"*"&C12&"*",'Observations '!$H:$H,IF(D12="","",D12),'Observations '!$D:$D,$F$2)+COUNTIFS('Observations '!$G:$G,"*"&C12&"*",'Observations '!$H:$H,IF(D12="","",D12),'Observations '!$D:$D,$F$3) -> 0 | G12: =COUNTIFS('Observations '!$G:$G,"*"&C12&"*",'Observations '!$H:$H,IF(D12="","",D12),'Observations '!$D:$D,$G$2) -> 0 | H12: =L12-E12-F12-G12 -> 1 | I12: =COUNTIFS('Observations '!$G:$G,"*"&C12&"*",'Observations '!$H:$H,IF(D12="","",D12),'Observations '!$E:$E,$I$2)+COUNTIFS('Observations '!$G:$G,"*"&C12&"*",'Observations '!$H:$H,IF(D12="","",D12),'Observations '!$E:$E,$I$3) -> 2 | J12: =COUNTIFS('Observations '!$G:$G,"*"&C12&"*",'Observations '!$H:$H,IF(D12="","",D12),'Observations '!$E:$E,$J$2)+COUNTIFS('Observations '!$G:$G,"*"&C12&"*",'Observations '!$H:$H,IF(D12="","",D12),'Observations '!$E:$E,$J$3) -> 0 | K12: =COUNTIFS('Observations '!$G:$G,"*"&C12&"*",'Observations '!$H:$H,IF(D12="","",D12),'Observations '!$E:$E,$K$2) -> 0 | L12: =SUM(I12:K12) -> 2
A13: WF | B13: 8 | C13: Scheduled jobs | D13: Work orders | E13: =COUNTIFS('Observations '!$G:$G,"*"&C13&"*",'Observations '!$H:$H,IF(D13="","",D13),'Observations '!$D:$D,$E$2) -> 1 | F13: =COUNTIFS('Observations '!$G:$G,"*"&C13&"*",'Observations '!$H:$H,IF(D13="","",D13),'Observations '!$D:$D,$F$2)+COUNTIFS('Observations '!$G:$G,"*"&C13&"*",'Observations '!$H:$H,IF(D13="","",D13),'Observations '!$D:$D,$F$3) -> 0 | G13: =COUNTIFS('Observations '!$G:$G,"*"&C13&"*",'Observations '!$H:$H,IF(D13="","",D13),'Observations '!$D:$D,$G$2) -> 0 | H13: =L13-E13-F13-G13 -> 1 | I13: =COUNTIFS('Observations '!$G:$G,"*"&C13&"*",'Observations '!$H:$H,IF(D13="","",D13),'Observations '!$E:$E,$I$2)+COUNTIFS('Observations '!$G:$G,"*"&C13&"*",'Observations '!$H:$H,IF(D13="","",D13),'Observations '!$E:$E,$I$3) -> 2 | J13: =COUNTIFS('Observations '!$G:$G,"*"&C13&"*",'Observations '!$H:$H,IF(D13="","",D13),'Observations '!$E:$E,$J$2)+COUNTIFS('Observations '!$G:$G,"*"&C13&"*",'Observations '!$H:$H,IF(D13="","",D13),'Observations '!$E:$E,$J$3) -> 0 | K13: =COUNTIFS('Observations '!$G:$G,"*"&C13&"*",'Observations '!$H:$H,IF(D13="","",D13),'Observations '!$E:$E,$K$2) -> 0 | L13: =SUM(I13:K13) -> 2
A14: Admin | B14: 9 | C14: Config Policies | D14: Password | E14: =COUNTIFS('Observations '!$G:$G,"*"&C14&"*",'Observations '!$H:$H,IF(D14="","",D14),'Observations '!$D:$D,$E$2) -> 1 | F14: =COUNTIFS('Observations '!$G:$G,"*"&C14&"*",'Observations '!$H:$H,IF(D14="","",D14),'Observations '!$D:$D,$F$2)+COUNTIFS('Observations '!$G:$G,"*"&C14&"*",'Observations '!$H:$H,IF(D14="","",D14),'Observations '!$D:$D,$F$3) -> 0 | G14: =COUNTIFS('Observations '!$G:$G,"*"&C14&"*",'Observations '!$H:$H,IF(D14="","",D14),'Observations '!$D:$D,$G$2) -> 0 | H14: =L14-E14-F14-G14 -> 1 | I14: =COUNTIFS('Observations '!$G:$G,"*"&C14&"*",'Observations '!$H:$H,IF(D14="","",D14),'Observations '!$E:$E,$I$2)+COUNTIFS('Observations '!$G:$G,"*"&C14&"*",'Observations '!$H:$H,IF(D14="","",D14),'Observations '!$E:$E,$I$3) -> 2 | J14: =COUNTIFS('Observations '!$G:$G,"*"&C14&"*",'Observations '!$H:$H,IF(D14="","",D14),'Observations '!$E:$E,$J$2)+COUNTIFS('Observations '!$G:$G,"*"&C14&"*",'Observations '!$H:$H,IF(D14="","",D14),'Observations '!$E:$E,$J$3) -> 0 | K14: =COUNTIFS('Observations '!$G:$G,"*"&C14&"*",'Observations '!$H:$H,IF(D14="","",D14),'Observations '!$E:$E,$K$2) -> 0 | L14: =SUM(I14:K14) -> 2
B15: 10 | C15: Config Policies | D15: Notification | E15: =COUNTIFS('Observations '!$G:$G,"*"&C15&"*",'Observations '!$H:$H,IF(D15="","",D15),'Observations '!$D:$D,$E$2) -> 1 | F15: =COUNTIFS('Observations '!$G:$G,"*"&C15&"*",'Observations '!$H:$H,IF(D15="","",D15),'Observations '!$D:$D,$F$2)+COUNTIFS('Observations '!$G:$G,"*"&C15&"*",'Observations '!$H:$H,IF(D15="","",D15),'Observations '!$D:$D,$F$3) -> 0 | G15: =COUNTIFS('Observations '!$G:$G,"*"&C15&"*",'Observations '!$H:$H,IF(D15="","",D15),'Observations '!$D:$D,$G$2) -> 0 | H15: =L15-E15-F15-G15 -> 1 | I15: =COUNTIFS('Observations '!$G:$G,"*"&C15&"*",'Observations '!$H:$H,IF(D15="","",D15),'Observations '!$E:$E,$I$2)+COUNTIFS('Observations '!$G:$G,"*"&C15&"*",'Observations '!$H:$H,IF(D15="","",D15),'Observations '!$E:$E,$I$3) -> 2 | J15: =COUNTIFS('Observations '!$G:$G,"*"&C15&"*",'Observations '!$H:$H,IF(D15="","",D15),'Observations '!$E:$E,$J$2)+COUNTIFS('Observations '!$G:$G,"*"&C15&"*",'Observations '!$H:$H,IF(D15="","",D15),'Observations '!$E:$E,$J$3) -> 0 | K15: =COUNTIFS('Observations '!$G:$G,"*"&C15&"*",'Observations '!$H:$H,IF(D15="","",D15),'Observations '!$E:$E,$K$2) -> 0 | L15: =SUM(I15:K15) -> 2
A16: APM | B16: 11 | C16: Config Policies | D16: PM generation | E16: =COUNTIFS('Observations '!$G:$G,"*"&C16&"*",'Observations '!$H:$H,IF(D16="","",D16),'Observations '!$D:$D,$E$2) -> 1 | F16: =COUNTIFS('Observations '!$G:$G,"*"&C16&"*",'Observations '!$H:$H,IF(D16="","",D16),'Observations '!$D:$D,$F$2)+COUNTIFS('Observations '!$G:$G,"*"&C16&"*",'Observations '!$H:$H,IF(D16="","",D16),'Observations '!$D:$D,$F$3) -> 0 | G16: =COUNTIFS('Observations '!$G:$G,"*"&C16&"*",'Observations '!$H:$H,IF(D16="","",D16),'Observations '!$D:$D,$G$2) -> 0 | H16: =L16-E16-F16-G16 -> 1 | I16: =COUNTIFS('Observations '!$G:$G,"*"&C16&"*",'Observations '!$H:$H,IF(D16="","",D16),'Observations '!$E:$E,$I$2)+COUNTIFS('Observations '!$G:$G,"*"&C16&"*",'Observations '!$H:$H,IF(D16="","",D16),'Observations '!$E:$E,$I$3) -> 2 | J16: =COUNTIFS('Observations '!$G:$G,"*"&C16&"*",'Observations '!$H:$H,IF(D16="","",D16),'Observations '!$E:$E,$J$2)+COUNTIFS('Observations '!$G:$G,"*"&C16&"*",'Observations '!$H:$H,IF(D16="","",D16),'Observations '!$E:$E,$J$3) -> 0 | K16: =COUNTIFS('Observations '!$G:$G,"*"&C16&"*",'Observations '!$H:$H,IF(D16="","",D16),'Observations '!$E:$E,$K$2) -> 0 | L16: =SUM(I16:K16) -> 2
B17: 12 | C17: Config Assets | D17: Asset types | E17: =COUNTIFS('Observations '!$G:$G,"*"&C17&"*",'Observations '!$H:$H,IF(D17="","",D17),'Observations '!$D:$D,$E$2) -> 0 | F17: =COUNTIFS('Observations '!$G:$G,"*"&C17&"*",'Observations '!$H:$H,IF(D17="","",D17),'Observations '!$D:$D,$F$2)+COUNTIFS('Observations '!$G:$G,"*"&C17&"*",'Observations '!$H:$H,IF(D17="","",D17),'Observations '!$D:$D,$F$3) -> 4 | G17: =COUNTIFS('Observations '!$G:$G,"*"&C17&"*",'Observations '!$H:$H,IF(D17="","",D17),'Observations '!$D:$D,$G$2) -> 1 | H17: =L17-E17-F17-G17 -> -1 | I17: =COUNTIFS('Observations '!$G:$G,"*"&C17&"*",'Observations '!$H:$H,IF(D17="","",D17),'Observations '!$E:$E,$I$2)+COUNTIFS('Observations '!$G:$G,"*"&C17&"*",'Observations '!$H:$H,IF(D17="","",D17),'Observations '!$E:$E,$I$3) -> 0 | J17: =COUNTIFS('Observations '!$G:$G,"*"&C17&"*",'Observations '!$H:$H,IF(D17="","",D17),'Observations '!$E:$E,$J$2)+COUNTIFS('Observations '!$G:$G,"*"&C17&"*",'Observations '!$H:$H,IF(D17="","",D17),'Observations '!$E:$E,$J$3) -> 0 | K17: =COUNTIFS('Observations '!$G:$G,"*"&C17&"*",'Observations '!$H:$H,IF(D17="","",D17),'Observations '!$E:$E,$K$2) -> 4 | L17: =SUM(I17:K17) -> 4
B18: 13 | C18: Config Assets | D18: Material Types | E18: =COUNTIFS('Observations '!$G:$G,"*"&C18&"*",'Observations '!$H:$H,IF(D18="","",D18),'Observations '!$D:$D,$E$2) -> 0 | F18: =COUNTIFS('Observations '!$G:$G,"*"&C18&"*",'Observations '!$H:$H,IF(D18="","",D18),'Observations '!$D:$D,$F$2)+COUNTIFS('Observations '!$G:$G,"*"&C18&"*",'Observations '!$H:$H,IF(D18="","",D18),'Observations '!$D:$D,$F$3) -> 1 | G18: =COUNTIFS('Observations '!$G:$G,"*"&C18&"*",'Observations '!$H:$H,IF(D18="","",D18),'Observations '!$D:$D,$G$2) -> 0 | H18: =L18-E18-F18-G18 -> 0 | I18: =COUNTIFS('Observations '!$G:$G,"*"&C18&"*",'Observations '!$H:$H,IF(D18="","",D18),'Observations '!$E:$E,$I$2)+COUNTIFS('Observations '!$G:$G,"*"&C18&"*",'Observations '!$H:$H,IF(D18="","",D18),'Observations '!$E:$E,$I$3) -> 0 | J18: =COUNTIFS('Observations '!$G:$G,"*"&C18&"*",'Observations '!$H:$H,IF(D18="","",D18),'Observations '!$E:$E,$J$2)+COUNTIFS('Observations '!$G:$G,"*"&C18&"*",'Observations '!$H:$H,IF(D18="","",D18),'Observations '!$E:$E,$J$3) -> 0 | K18: =COUNTIFS('Observations '!$G:$G,"*"&C18&"*",'Observations '!$H:$H,IF(D18="","",D18),'Observations '!$E:$E,$K$2) -> 1 | L18: =SUM(I18:K18) -> 1
A19: meter | B19: 14 | C19: Config Assets | D19: Meter Types | E19: =COUNTIFS('Observations '!$G:$G,"*"&C19&"*",'Observations '!$H:$H,IF(D19="","",D19),'Observations '!$D:$D,$E$2) -> 0 | F19: =COUNTIFS('Observations '!$G:$G,"*"&C19&"*",'Observations '!$H:$H,IF(D19="","",D19),'Observations '!$D:$D,$F$2)+COUNTIFS('Observations '!$G:$G,"*"&C19&"*",'Observations '!$H:$H,IF(D19="","",D19),'Observations '!$D:$D,$F$3) -> 2 | G19: =COUNTIFS('Observations '!$G:$G,"*"&C19&"*",'Observations '!$H:$H,IF(D19="","",D19),'Observations '!$D:$D,$G$2) -> 1 | H19: =L19-E19-F19-G19 -> 0 | I19: =COUNTIFS('Observations '!$G:$G,"*"&C19&"*",'Observations '!$H:$H,IF(D19="","",D19),'Observations '!$E:$E,$I$2)+COUNTIFS('Observations '!$G:$G,"*"&C19&"*",'Observations '!$H:$H,IF(D19="","",D19),'Observations '!$E:$E,$I$3) -> 0 | J19: =COUNTIFS('Observations '!$G:$G,"*"&C19&"*",'Observations '!$H:$H,IF(D19="","",D19),'Observations '!$E:$E,$J$2)+COUNTIFS('Observations '!$G:$G,"*"&C19&"*",'Observations '!$H:$H,IF(D19="","",D19),'Observations '!$E:$E,$J$3) -> 2 | K19: =COUNTIFS('Observations '!$G:$G,"*"&C19&"*",'Observations '!$H:$H,IF(D19="","",D19),'Observations '!$E:$E,$K$2) -> 1 | L19: =SUM(I19:K19) -> 3
B20: 15 | C20: General | E20: =COUNTIFS('Observations '!$G:$G,"*"&C20&"*",'Observations '!$H:$H,IF(D20="","",D20),'Observations '!$D:$D,$E$2) -> 0 | F20: =COUNTIFS('Observations '!$G:$G,"*"&C20&"*",'Observations '!$H:$H,IF(D20="","",D20),'Observations '!$D:$D,$F$2)+COUNTIFS('Observations '!$G:$G,"*"&C20&"*",'Observations '!$H:$H,IF(D20="","",D20),'Observations '!$D:$D,$F$3) -> 2 | G20: =COUNTIFS('Observations '!$G:$G,"*"&C20&"*",'Observations '!$H:$H,IF(D20="","",D20),'Observations '!$D:$D,$G$2) -> 0 | H20: =L20-E20-F20-G20 -> 1 | I20: =COUNTIFS('Observations '!$G:$G,"*"&C20&"*",'Observations '!$H:$H,IF(D20="","",D20),'Observations '!$E:$E,$I$2)+COUNTIFS('Observations '!$G:$G,"*"&C20&"*",'Observations '!$H:$H,IF(D20="","",D20),'Observations '!$E:$E,$I$3) -> 0 | J20: =COUNTIFS('Observations '!$G:$G,"*"&C20&"*",'Observations '!$H:$H,IF(D20="","",D20),'Observations '!$E:$E,$J$2)+COUNTIFS('Observations '!$G:$G,"*"&C20&"*",'Observations '!$H:$H,IF(D20="","",D20),'Observations '!$E:$E,$J$3) -> 2 | K20: =COUNTIFS('Observations '!$G:$G,"*"&C20&"*",'Observations '!$H:$H,IF(D20="","",D20),'Observations '!$E:$E,$K$2) -> 1 | L20: =SUM(I20:K20) -> 3
B21: 16 | C21: Schedule types | E21: =COUNTIFS('Observations '!$G:$G,"*"&C21&"*",'Observations '!$H:$H,IF(D21="","",D21),'Observations '!$D:$D,$E$2) -> 1 | F21: =COUNTIFS('Observations '!$G:$G,"*"&C21&"*",'Observations '!$H:$H,IF(D21="","",D21),'Observations '!$D:$D,$F$2)+COUNTIFS('Observations '!$G:$G,"*"&C21&"*",'Observations '!$H:$H,IF(D21="","",D21),'Observations '!$D:$D,$F$3) -> 1 | G21: =COUNTIFS('Observations '!$G:$G,"*"&C21&"*",'Observations '!$H:$H,IF(D21="","",D21),'Observations '!$D:$D,$G$2) -> 3 | H21: =L21-E21-F21-G21 -> -2 | I21: =COUNTIFS('Observations '!$G:$G,"*"&C21&"*",'Observations '!$H:$H,IF(D21="","",D21),'Observations '!$E:$E,$I$2)+COUNTIFS('Observations '!$G:$G,"*"&C21&"*",'Observations '!$H:$H,IF(D21="","",D21),'Observations '!$E:$E,$I$3) -> 0 | J21: =COUNTIFS('Observations '!$G:$G,"*"&C21&"*",'Observations '!$H:$H,IF(D21="","",D21),'Observations '!$E:$E,$J$2)+COUNTIFS('Observations '!$G:$G,"*"&C21&"*",'Observations '!$H:$H,IF(D21="","",D21),'Observations '!$E:$E,$J$3) -> 2 | K21: =COUNTIFS('Observations '!$G:$G,"*"&C21&"*",'Observations '!$H:$H,IF(D21="","",D21),'Observations '!$E:$E,$K$2) -> 1 | L21: =SUM(I21:K21) -> 3
B22: 17 | C22: Sections | E22: =COUNTIFS('Observations '!$G:$G,"*"&C22&"*",'Observations '!$H:$H,IF(D22="","",D22),'Observations '!$D:$D,$E$2) -> 0 | F22: =COUNTIFS('Observations '!$G:$G,"*"&C22&"*",'Observations '!$H:$H,IF(D22="","",D22),'Observations '!$D:$D,$F$2)+COUNTIFS('Observations '!$G:$G,"*"&C22&"*",'Observations '!$H:$H,IF(D22="","",D22),'Observations '!$D:$D,$F$3) -> 2 | G22: =COUNTIFS('Observations '!$G:$G,"*"&C22&"*",'Observations '!$H:$H,IF(D22="","",D22),'Observations '!$D:$D,$G$2) -> 0 | H22: =L22-E22-F22-G22 -> 1 | I22: =COUNTIFS('Observations '!$G:$G,"*"&C22&"*",'Observations '!$H:$H,IF(D22="","",D22),'Observations '!$E:$E,$I$2)+COUNTIFS('Observations '!$G:$G,"*"&C22&"*",'Observations '!$H:$H,IF(D22="","",D22),'Observations '!$E:$E,$I$3) -> 0 | J22: =COUNTIFS('Observations '!$G:$G,"*"&C22&"*",'Observations '!$H:$H,IF(D22="","",D22),'Observations '!$E:$E,$J$2)+COUNTIFS('Observations '!$G:$G,"*"&C22&"*",'Observations '!$H:$H,IF(D22="","",D22),'Observations '!$E:$E,$J$3) -> 2 | K22: =COUNTIFS('Observations '!$G:$G,"*"&C22&"*",'Observations '!$H:$H,IF(D22="","",D22),'Observations '!$E:$E,$K$2) -> 1 | L22: =SUM(I22:K22) -> 3
A23: MMP | B23: 18 | C23: Configuration Maintenance | D23: MMP | E23: =COUNTIFS('Observations '!$G:$G,"*"&C23&"*",'Observations '!$H:$H,IF(D23="","",D23),'Observations '!$D:$D,$E$2) -> 0 | F23: =COUNTIFS('Observations '!$G:$G,"*"&C23&"*",'Observations '!$H:$H,IF(D23="","",D23),'Observations '!$D:$D,$F$2)+COUNTIFS('Observations '!$G:$G,"*"&C23&"*",'Observations '!$H:$H,IF(D23="","",D23),'Observations '!$D:$D,$F$3) -> 1 | G23: =COUNTIFS('Observations '!$G:$G,"*"&C23&"*",'Observations '!$H:$H,IF(D23="","",D23),'Observations '!$D:$D,$G$2) -> 0 | H23: =L23-E23-F23-G23 -> 1 | I23: =COUNTIFS('Observations '!$G:$G,"*"&C23&"*",'Observations '!$H:$H,IF(D23="","",D23),'Observations '!$E:$E,$I$2)+COUNTIFS('Observations '!$G:$G,"*"&C23&"*",'Observations '!$H:$H,IF(D23="","",D23),'Observations '!$E:$E,$I$3) -> 2 | J23: =COUNTIFS('Observations '!$G:$G,"*"&C23&"*",'Observations '!$H:$H,IF(D23="","",D23),'Observations '!$E:$E,$J$2)+COUNTIFS('Observations '!$G:$G,"*"&C23&"*",'Observations '!$H:$H,IF(D23="","",D23),'Observations '!$E:$E,$J$3) -> 0 | K23: =COUNTIFS('Observations '!$G:$G,"*"&C23&"*",'Observations '!$H:$H,IF(D23="","",D23),'Observations '!$E:$E,$K$2) -> 0 | L23: =SUM(I23:K23) -> 2
B24: 19 | C24: Config Setup | D24: Master Workflows | E24: =COUNTIFS('Observations '!$G:$G,"*"&C24&"*",'Observations '!$H:$H,IF(D24="","",D24),'Observations '!$D:$D,$E$2) -> 0 | F24: =COUNTIFS('Observations '!$G:$G,"*"&C24&"*",'Observations '!$H:$H,IF(D24="","",D24),'Observations '!$D:$D,$F$2)+COUNTIFS('Observations '!$G:$G,"*"&C24&"*",'Observations '!$H:$H,IF(D24="","",D24),'Observations '!$D:$D,$F$3) -> 1 | G24: =COUNTIFS('Observations '!$G:$G,"*"&C24&"*",'Observations '!$H:$H,IF(D24="","",D24),'Observations '!$D:$D,$G$2) -> 0 | H24: =L24-E24-F24-G24 -> 1 | I24: =COUNTIFS('Observations '!$G:$G,"*"&C24&"*",'Observations '!$H:$H,IF(D24="","",D24),'Observations '!$E:$E,$I$2)+COUNTIFS('Observations '!$G:$G,"*"&C24&"*",'Observations '!$H:$H,IF(D24="","",D24),'Observations '!$E:$E,$I$3) -> 0 | J24: =COUNTIFS('Observations '!$G:$G,"*"&C24&"*",'Observations '!$H:$H,IF(D24="","",D24),'Observations '!$E:$E,$J$2)+COUNTIFS('Observations '!$G:$G,"*"&C24&"*",'Observations '!$H:$H,IF(D24="","",D24),'Observations '!$E:$E,$J$3) -> 2 | K24: =COUNTIFS('Observations '!$G:$G,"*"&C24&"*",'Observations '!$H:$H,IF(D24="","",D24),'Observations '!$E:$E,$K$2) -> 0 | L24: =SUM(I24:K24) -> 2
B25: 20 | C25: Config Assets | D25: Car Asset Layout | E25: =COUNTIFS('Observations '!$G:$G,"*"&C25&"*",'Observations '!$H:$H,IF(D25="","",D25),'Observations '!$D:$D,$E$2) -> 0 | F25: =COUNTIFS('Observations '!$G:$G,"*"&C25&"*",'Observations '!$H:$H,IF(D25="","",D25),'Observations '!$D:$D,$F$2)+COUNTIFS('Observations '!$G:$G,"*"&C25&"*",'Observations '!$H:$H,IF(D25="","",D25),'Observations '!$D:$D,$F$3) -> 1 | G25: =COUNTIFS('Observations '!$G:$G,"*"&C25&"*",'Observations '!$H:$H,IF(D25="","",D25),'Observations '!$D:$D,$G$2) -> 0 | H25: =L25-E25-F25-G25 -> 1 | I25: =COUNTIFS('Observations '!$G:$G,"*"&C25&"*",'Observations '!$H:$H,IF(D25="","",D25),'Observations '!$E:$E,$I$2)+COUNTIFS('Observations '!$G:$G,"*"&C25&"*",'Observations '!$H:$H,IF(D25="","",D25),'Observations '!$E:$E,$I$3) -> 0 | J25: =COUNTIFS('Observations '!$G:$G,"*"&C25&"*",'Observations '!$H:$H,IF(D25="","",D25),'Observations '!$E:$E,$J$2)+COUNTIFS('Observations '!$G:$G,"*"&C25&"*",'Observations '!$H:$H,IF(D25="","",D25),'Observations '!$E:$E,$J$3) -> 2 | K25: =COUNTIFS('Observations '!$G:$G,"*"&C25&"*",'Observations '!$H:$H,IF(D25="","",D25),'Observations '!$E:$E,$K$2) -> 0 | L25: =SUM(I25:K25) -> 2
B26: 21 | C26: Config Assets | D26: Car types | E26: =COUNTIFS('Observations '!$G:$G,"*"&C26&"*",'Observations '!$H:$H,IF(D26="","",D26),'Observations '!$D:$D,$E$2) -> 0 | F26: =COUNTIFS('Observations '!$G:$G,"*"&C26&"*",'Observations '!$H:$H,IF(D26="","",D26),'Observations '!$D:$D,$F$2)+COUNTIFS('Observations '!$G:$G,"*"&C26&"*",'Observations '!$H:$H,IF(D26="","",D26),'Observations '!$D:$D,$F$3) -> 1 | G26: =COUNTIFS('Observations '!$G:$G,"*"&C26&"*",'Observations '!$H:$H,IF(D26="","",D26),'Observations '!$D:$D,$G$2) -> 0 | H26: =L26-E26-F26-G26 -> 1 | I26: =COUNTIFS('Observations '!$G:$G,"*"&C26&"*",'Observations '!$H:$H,IF(D26="","",D26),'Observations '!$E:$E,$I$2)+COUNTIFS('Observations '!$G:$G,"*"&C26&"*",'Observations '!$H:$H,IF(D26="","",D26),'Observations '!$E:$E,$I$3) -> 0 | J26: =COUNTIFS('Observations '!$G:$G,"*"&C26&"*",'Observations '!$H:$H,IF(D26="","",D26),'Observations '!$E:$E,$J$2)+COUNTIFS('Observations '!$G:$G,"*"&C26&"*",'Observations '!$H:$H,IF(D26="","",D26),'Observations '!$E:$E,$J$3) -> 2 | K26: =COUNTIFS('Observations '!$G:$G,"*"&C26&"*",'Observations '!$H:$H,IF(D26="","",D26),'Observations '!$E:$E,$K$2) -> 0 | L26: =SUM(I26:K26) -> 2
B27: 22 | C27: Config Assets | D27: Trainset types | E27: =COUNTIFS('Observations '!$G:$G,"*"&C27&"*",'Observations '!$H:$H,IF(D27="","",D27),'Observations '!$D:$D,$E$2) -> 0 | F27: =COUNTIFS('Observations '!$G:$G,"*"&C27&"*",'Observations '!$H:$H,IF(D27="","",D27),'Observations '!$D:$D,$F$2)+COUNTIFS('Observations '!$G:$G,"*"&C27&"*",'Observations '!$H:$H,IF(D27="","",D27),'Observations '!$D:$D,$F$3) -> 2 | G27: =COUNTIFS('Observations '!$G:$G,"*"&C27&"*",'Observations '!$H:$H,IF(D27="","",D27),'Observations '!$D:$D,$G$2) -> 0 | H27: =L27-E27-F27-G27 -> 2 | I27: =COUNTIFS('Observations '!$G:$G,"*"&C27&"*",'Observations '!$H:$H,IF(D27="","",D27),'Observations '!$E:$E,$I$2)+COUNTIFS('Observations '!$G:$G,"*"&C27&"*",'Observations '!$H:$H,IF(D27="","",D27),'Observations '!$E:$E,$I$3) -> 0 | J27: =COUNTIFS('Observations '!$G:$G,"*"&C27&"*",'Observations '!$H:$H,IF(D27="","",D27),'Observations '!$E:$E,$J$2)+COUNTIFS('Observations '!$G:$G,"*"&C27&"*",'Observations '!$H:$H,IF(D27="","",D27),'Observations '!$E:$E,$J$3) -> 4 | K27: =COUNTIFS('Observations '!$G:$G,"*"&C27&"*",'Observations '!$H:$H,IF(D27="","",D27),'Observations '!$E:$E,$K$2) -> 0 | L27: =SUM(I27:K27) -> 4
B28: 23 | C28: Asset/make/Model vs Sch types | D28: Association of Schedules not only based on asset types, but also based on make and model | E28: =COUNTIFS('Observations '!$G:$G,"*"&C28&"*",'Observations '!$H:$H,IF(D28="","",D28),'Observations '!$D:$D,$E$2) -> 0 | F28: =COUNTIFS('Observations '!$G:$G,"*"&C28&"*",'Observations '!$H:$H,IF(D28="","",D28),'Observations '!$D:$D,$F$2)+COUNTIFS('Observations '!$G:$G,"*"&C28&"*",'Observations '!$H:$H,IF(D28="","",D28),'Observations '!$D:$D,$F$3) -> 1 | G28: =COUNTIFS('Observations '!$G:$G,"*"&C28&"*",'Observations '!$H:$H,IF(D28="","",D28),'Observations '!$D:$D,$G$2) -> 0 | H28: =L28-E28-F28-G28 -> 1 | I28: =COUNTIFS('Observations '!$G:$G,"*"&C28&"*",'Observations '!$H:$H,IF(D28="","",D28),'Observations '!$E:$E,$I$2)+COUNTIFS('Observations '!$G:$G,"*"&C28&"*",'Observations '!$H:$H,IF(D28="","",D28),'Observations '!$E:$E,$I$3) -> 2 | J28: =COUNTIFS('Observations '!$G:$G,"*"&C28&"*",'Observations '!$H:$H,IF(D28="","",D28),'Observations '!$E:$E,$J$2)+COUNTIFS('Observations '!$G:$G,"*"&C28&"*",'Observations '!$H:$H,IF(D28="","",D28),'Observations '!$E:$E,$J$3) -> 0 | K28: =COUNTIFS('Observations '!$G:$G,"*"&C28&"*",'Observations '!$H:$H,IF(D28="","",D28),'Observations '!$E:$E,$K$2) -> 0 | L28: =SUM(I28:K28) -> 2
B29: 24 | C29: Job plan Checklist | D29: based on AT make and model - if situation demands | E29: =COUNTIFS('Observations '!$G:$G,"*"&C29&"*",'Observations '!$H:$H,IF(D29="","",D29),'Observations '!$D:$D,$E$2) -> 0 | F29: =COUNTIFS('Observations '!$G:$G,"*"&C29&"*",'Observations '!$H:$H,IF(D29="","",D29),'Observations '!$D:$D,$F$2)+COUNTIFS('Observations '!$G:$G,"*"&C29&"*",'Observations '!$H:$H,IF(D29="","",D29),'Observations '!$D:$D,$F$3) -> 1 | G29: =COUNTIFS('Observations '!$G:$G,"*"&C29&"*",'Observations '!$H:$H,IF(D29="","",D29),'Observations '!$D:$D,$G$2) -> 0 | H29: =L29-E29-F29-G29 -> 1 | I29: =COUNTIFS('Observations '!$G:$G,"*"&C29&"*",'Observations '!$H:$H,IF(D29="","",D29),'Observations '!$E:$E,$I$2)+COUNTIFS('Observations '!$G:$G,"*"&C29&"*",'Observations '!$H:$H,IF(D29="","",D29),'Observations '!$E:$E,$I$3) -> 0 | J29: =COUNTIFS('Observations '!$G:$G,"*"&C29&"*",'Observations '!$H:$H,IF(D29="","",D29),'Observations '!$E:$E,$J$2)+COUNTIFS('Observations '!$G:$G,"*"&C29&"*",'Observations '!$H:$H,IF(D29="","",D29),'Observations '!$E:$E,$J$3) -> 2 | K29: =COUNTIFS('Observations '!$G:$G,"*"&C29&"*",'Observations '!$H:$H,IF(D29="","",D29),'Observations '!$E:$E,$K$2) -> 0 | L29: =SUM(I29:K29) -> 2
B30: 25 | C30: Engineering sections (Sub units/Depts) | E30: =COUNTIFS('Observations '!$G:$G,"*"&C30&"*",'Observations '!$H:$H,IF(D30="","",D30),'Observations '!$D:$D,$E$2) -> 0 | F30: =COUNTIFS('Observations '!$G:$G,"*"&C30&"*",'Observations '!$H:$H,IF(D30="","",D30),'Observations '!$D:$D,$F$2)+COUNTIFS('Observations '!$G:$G,"*"&C30&"*",'Observations '!$H:$H,IF(D30="","",D30),'Observations '!$D:$D,$F$3) -> 1 | G30: =COUNTIFS('Observations '!$G:$G,"*"&C30&"*",'Observations '!$H:$H,IF(D30="","",D30),'Observations '!$D:$D,$G$2) -> 0 | H30: =L30-E30-F30-G30 -> 1 | I30: =COUNTIFS('Observations '!$G:$G,"*"&C30&"*",'Observations '!$H:$H,IF(D30="","",D30),'Observations '!$E:$E,$I$2)+COUNTIFS('Observations '!$G:$G,"*"&C30&"*",'Observations '!$H:$H,IF(D30="","",D30),'Observations '!$E:$E,$I$3) -> 0 | J30: =COUNTIFS('Observations '!$G:$G,"*"&C30&"*",'Observations '!$H:$H,IF(D30="","",D30),'Observations '!$E:$E,$J$2)+COUNTIFS('Observations '!$G:$G,"*"&C30&"*",'Observations '!$H:$H,IF(D30="","",D30),'Observations '!$E:$E,$J$3) -> 2 | K30: =COUNTIFS('Observations '!$G:$G,"*"&C30&"*",'Observations '!$H:$H,IF(D30="","",D30),'Observations '!$E:$E,$K$2) -> 0 | L30: =SUM(I30:K30) -> 2
B31: 26 | C31: Landscape (Identify impacted landscapes) | E31: =COUNTIFS('Observations '!$G:$G,"*"&C31&"*",'Observations '!$H:$H,IF(D31="","",D31),'Observations '!$D:$D,$E$2) -> 0 | F31: =COUNTIFS('Observations '!$G:$G,"*"&C31&"*",'Observations '!$H:$H,IF(D31="","",D31),'Observations '!$D:$D,$F$2)+COUNTIFS('Observations '!$G:$G,"*"&C31&"*",'Observations '!$H:$H,IF(D31="","",D31),'Observations '!$D:$D,$F$3) -> 1 | G31: =COUNTIFS('Observations '!$G:$G,"*"&C31&"*",'Observations '!$H:$H,IF(D31="","",D31),'Observations '!$D:$D,$G$2) -> 0 | H31: =L31-E31-F31-G31 -> 1 | I31: =COUNTIFS('Observations '!$G:$G,"*"&C31&"*",'Observations '!$H:$H,IF(D31="","",D31),'Observations '!$E:$E,$I$2)+COUNTIFS('Observations '!$G:$G,"*"&C31&"*",'Observations '!$H:$H,IF(D31="","",D31),'Observations '!$E:$E,$I$3) -> 0 | J31: =COUNTIFS('Observations '!$G:$G,"*"&C31&"*",'Observations '!$H:$H,IF(D31="","",D31),'Observations '!$E:$E,$J$2)+COUNTIFS('Observations '!$G:$G,"*"&C31&"*",'Observations '!$H:$H,IF(D31="","",D31),'Observations '!$E:$E,$J$3) -> 2 | K31: =COUNTIFS('Observations '!$G:$G,"*"&C31&"*",'Observations '!$H:$H,IF(D31="","",D31),'Observations '!$E:$E,$K$2) -> 0 | L31: =SUM(I31:K31) -> 2
B32: 27 | C32: Fault codes | E32: =COUNTIFS('Observations '!$G:$G,"*"&C32&"*",'Observations '!$H:$H,IF(D32="","",D32),'Observations '!$D:$D,$E$2) -> 0 | F32: =COUNTIFS('Observations '!$G:$G,"*"&C32&"*",'Observations '!$H:$H,IF(D32="","",D32),'Observations '!$D:$D,$F$2)+COUNTIFS('Observations '!$G:$G,"*"&C32&"*",'Observations '!$H:$H,IF(D32="","",D32),'Observations '!$D:$D,$F$3) -> 1 | G32: =COUNTIFS('Observations '!$G:$G,"*"&C32&"*",'Observations '!$H:$H,IF(D32="","",D32),'Observations '!$D:$D,$G$2) -> 0 | H32: =L32-E32-F32-G32 -> 1 | I32: =COUNTIFS('Observations '!$G:$G,"*"&C32&"*",'Observations '!$H:$H,IF(D32="","",D32),'Observations '!$E:$E,$I$2)+COUNTIFS('Observations '!$G:$G,"*"&C32&"*",'Observations '!$H:$H,IF(D32="","",D32),'Observations '!$E:$E,$I$3) -> 0 | J32: =COUNTIFS('Observations '!$G:$G,"*"&C32&"*",'Observations '!$H:$H,IF(D32="","",D32),'Observations '!$E:$E,$J$2)+COUNTIFS('Observations '!$G:$G,"*"&C32&"*",'Observations '!$H:$H,IF(D32="","",D32),'Observations '!$E:$E,$J$3) -> 2 | K32: =COUNTIFS('Observations '!$G:$G,"*"&C32&"*",'Observations '!$H:$H,IF(D32="","",D32),'Observations '!$E:$E,$K$2) -> 0 | L32: =SUM(I32:K32) -> 2
B33: 28 | C33: Functional Units | E33: =COUNTIFS('Observations '!$G:$G,"*"&C33&"*",'Observations '!$H:$H,IF(D33="","",D33),'Observations '!$D:$D,$E$2) -> 0 | F33: =COUNTIFS('Observations '!$G:$G,"*"&C33&"*",'Observations '!$H:$H,IF(D33="","",D33),'Observations '!$D:$D,$F$2)+COUNTIFS('Observations '!$G:$G,"*"&C33&"*",'Observations '!$H:$H,IF(D33="","",D33),'Observations '!$D:$D,$F$3) -> 1 | G33: =COUNTIFS('Observations '!$G:$G,"*"&C33&"*",'Observations '!$H:$H,IF(D33="","",D33),'Observations '!$D:$D,$G$2) -> 0 | H33: =L33-E33-F33-G33 -> -1 | I33: =COUNTIFS('Observations '!$G:$G,"*"&C33&"*",'Observations '!$H:$H,IF(D33="","",D33),'Observations '!$E:$E,$I$2)+COUNTIFS('Observations '!$G:$G,"*"&C33&"*",'Observations '!$H:$H,IF(D33="","",D33),'Observations '!$E:$E,$I$3) -> 0 | J33: =COUNTIFS('Observations '!$G:$G,"*"&C33&"*",'Observations '!$H:$H,IF(D33="","",D33),'Observations '!$E:$E,$J$2)+COUNTIFS('Observations '!$G:$G,"*"&C33&"*",'Observations '!$H:$H,IF(D33="","",D33),'Observations '!$E:$E,$J$3) -> 0 | K33: =COUNTIFS('Observations '!$G:$G,"*"&C33&"*",'Observations '!$H:$H,IF(D33="","",D33),'Observations '!$E:$E,$K$2) -> 0 | L33: =SUM(I33:K33) -> 0
B34: 29 | C34: PTW screen | E34: =COUNTIFS('Observations '!$G:$G,"*"&C34&"*",'Observations '!$H:$H,IF(D34="","",D34),'Observations '!$D:$D,$E$2) -> 1 | F34: =COUNTIFS('Observations '!$G:$G,"*"&C34&"*",'Observations '!$H:$H,IF(D34="","",D34),'Observations '!$D:$D,$F$2)+COUNTIFS('Observations '!$G:$G,"*"&C34&"*",'Observations '!$H:$H,IF(D34="","",D34),'Observations '!$D:$D,$F$3) -> 0 | G34: =COUNTIFS('Observations '!$G:$G,"*"&C34&"*",'Observations '!$H:$H,IF(D34="","",D34),'Observations '!$D:$D,$G$2) -> 0 | H34: =L34-E34-F34-G34 -> 1 | I34: =COUNTIFS('Observations '!$G:$G,"*"&C34&"*",'Observations '!$H:$H,IF(D34="","",D34),'Observations '!$E:$E,$I$2)+COUNTIFS('Observations '!$G:$G,"*"&C34&"*",'Observations '!$H:$H,IF(D34="","",D34),'Observations '!$E:$E,$I$3) -> 2 | J34: =COUNTIFS('Observations '!$G:$G,"*"&C34&"*",'Observations '!$H:$H,IF(D34="","",D34),'Observations '!$E:$E,$J$2)+COUNTIFS('Observations '!$G:$G,"*"&C34&"*",'Observations '!$H:$H,IF(D34="","",D34),'Observations '!$E:$E,$J$3) -> 0 | K34: =COUNTIFS('Observations '!$G:$G,"*"&C34&"*",'Observations '!$H:$H,IF(D34="","",D34),'Observations '!$E:$E,$K$2) -> 0 | L34: =SUM(I34:K34) -> 2
B35: 30 | C35: Job Plan | E35: =COUNTIFS('Observations '!$G:$G,"*"&C35&"*",'Observations '!$H:$H,IF(D35="","",D35),'Observations '!$D:$D,$E$2) -> 0 | F35: =COUNTIFS('Observations '!$G:$G,"*"&C35&"*",'Observations '!$H:$H,IF(D35="","",D35),'Observations '!$D:$D,$F$2)+COUNTIFS('Observations '!$G:$G,"*"&C35&"*",'Observations '!$H:$H,IF(D35="","",D35),'Observations '!$D:$D,$F$3) -> 1 | G35: =COUNTIFS('Observations '!$G:$G,"*"&C35&"*",'Observations '!$H:$H,IF(D35="","",D35),'Observations '!$D:$D,$G$2) -> 3 | H35: =L35-E35-F35-G35 -> -2 | I35: =COUNTIFS('Observations '!$G:$G,"*"&C35&"*",'Observations '!$H:$H,IF(D35="","",D35),'Observations '!$E:$E,$I$2)+COUNTIFS('Observations '!$G:$G,"*"&C35&"*",'Observations '!$H:$H,IF(D35="","",D35),'Observations '!$E:$E,$I$3) -> 0 | J35: =COUNTIFS('Observations '!$G:$G,"*"&C35&"*",'Observations '!$H:$H,IF(D35="","",D35),'Observations '!$E:$E,$J$2)+COUNTIFS('Observations '!$G:$G,"*"&C35&"*",'Observations '!$H:$H,IF(D35="","",D35),'Observations '!$E:$E,$J$3) -> 2 | K35: =COUNTIFS('Observations '!$G:$G,"*"&C35&"*",'Observations '!$H:$H,IF(D35="","",D35),'Observations '!$E:$E,$K$2) -> 0 | L35: =SUM(I35:K35) -> 2
B36: 31 | C36: Checksheet | E36: =COUNTIFS('Observations '!$G:$G,"*"&C36&"*",'Observations '!$H:$H,IF(D36="","",D36),'Observations '!$D:$D,$E$2) -> 1 | F36: =COUNTIFS('Observations '!$G:$G,"*"&C36&"*",'Observations '!$H:$H,IF(D36="","",D36),'Observations '!$D:$D,$F$2)+COUNTIFS('Observations '!$G:$G,"*"&C36&"*",'Observations '!$H:$H,IF(D36="","",D36),'Observations '!$D:$D,$F$3) -> 1 | G36: =COUNTIFS('Observations '!$G:$G,"*"&C36&"*",'Observations '!$H:$H,IF(D36="","",D36),'Observations '!$D:$D,$G$2) -> 1 | H36: =L36-E36-F36-G36 -> -1 | I36: =COUNTIFS('Observations '!$G:$G,"*"&C36&"*",'Observations '!$H:$H,IF(D36="","",D36),'Observations '!$E:$E,$I$2)+COUNTIFS('Observations '!$G:$G,"*"&C36&"*",'Observations '!$H:$H,IF(D36="","",D36),'Observations '!$E:$E,$I$3) -> 0 | J36: =COUNTIFS('Observations '!$G:$G,"*"&C36&"*",'Observations '!$H:$H,IF(D36="","",D36),'Observations '!$E:$E,$J$2)+COUNTIFS('Observations '!$G:$G,"*"&C36&"*",'Observations '!$H:$H,IF(D36="","",D36),'Observations '!$E:$E,$J$3) -> 0 | K36: =COUNTIFS('Observations '!$G:$G,"*"&C36&"*",'Observations '!$H:$H,IF(D36="","",D36),'Observations '!$E:$E,$K$2) -> 2 | L36: =SUM(I36:K36) -> 2
B37: 32 | C37: Master Maintenance plan | E37: =COUNTIFS('Observations '!$G:$G,"*"&C37&"*",'Observations '!$H:$H,IF(D37="","",D37),'Observations '!$D:$D,$E$2) -> 0 | F37: =COUNTIFS('Observations '!$G:$G,"*"&C37&"*",'Observations '!$H:$H,IF(D37="","",D37),'Observations '!$D:$D,$F$2)+COUNTIFS('Observations '!$G:$G,"*"&C37&"*",'Observations '!$H:$H,IF(D37="","",D37),'Observations '!$D:$D,$F$3) -> 3 | G37: =COUNTIFS('Observations '!$G:$G,"*"&C37&"*",'Observations '!$H:$H,IF(D37="","",D37),'Observations '!$D:$D,$G$2) -> 4 | H37: =L37-E37-F37-G37 -> -1 | I37: =COUNTIFS('Observations '!$G:$G,"*"&C37&"*",'Observations '!$H:$H,IF(D37="","",D37),'Observations '!$E:$E,$I$2)+COUNTIFS('Observations '!$G:$G,"*"&C37&"*",'Observations '!$H:$H,IF(D37="","",D37),'Observations '!$E:$E,$I$3) -> 6 | J37: =COUNTIFS('Observations '!$G:$G,"*"&C37&"*",'Observations '!$H:$H,IF(D37="","",D37),'Observations '!$E:$E,$J$2)+COUNTIFS('Observations '!$G:$G,"*"&C37&"*",'Observations '!$H:$H,IF(D37="","",D37),'Observations '!$E:$E,$J$3) -> 0 | K37: =COUNTIFS('Observations '!$G:$G,"*"&C37&"*",'Observations '!$H:$H,IF(D37="","",D37),'Observations '!$E:$E,$K$2) -> 0 | L37: =SUM(I37:K37) -> 6
